Workbook

Sheet Conditions
B2: Seed | C2: Coverage | D2: Symmetry | E2: Granul. | F2: Samples | G2: Support Qty
B3: 632456723 | C3: Complete | D3: Yes | E3: vfine | F3: 3 | G3: Yes
B4: 632456723 | C4: Partial | D4: No | E4: vfine | F4: 3
B5: 632456723 | C5: Partial | D5: Yes | E5: regular | F5: 3 | G5: No
B6: 632456723 | C6: Partial | D6: Yes | E6: vfine | F6: 6
B7: 102370435 | C7: Partial | D7: Yes | E7: vfine | F7: 3 | I7: Finished
B8: 102370435 | C8: Complete | D8: No | E8: vfine | F8: 3 | G8: Yes | I8: Needs Slicing
B9: 102370435 | C9: Partial | D9: Yes | E9: regular | F9: 3 | G9: No | I9: Slicing
B10: 102370435 | C10: Partial | D10: Yes | E10: vfine | F10: 6 | G10: No | I10: Running
B11: 914023457 | C11: Complete | D11: Yes | E11: vfine | F11: 3 | G11: No | I11: Pending
B12: 914023458 | C12: Partial | D12: No | E12: vfine | F12: 3
B13: 914023459 | C13: Partial | D13: Yes | E13: regular | F13: 3 | G13: No
B14: 914023460 | C14: Partial | D14: Yes | E14: vfine | F14: 6 | G14: No

Sheet Original Comparison
A1: Parallelobox | F1: Symmetry-Based Decomposition | L1: Harpe | S1: Cube Skeleton Based Decomposition
A2: Model | B2: # Printers | C2: Parallel Time (seconds) | D2: Parallel Time (mins) | F2: Model | G2: # Printers | H2: Parallel Time (seconds) | I2: Parallel Time (mins) | J2: Parallelobox Improvement | L2: Model | M2: # Parts | N2: Parallel Time (seconds) | O2: Parallel Time (mins) | P2: Parallelobox Improvement | Q2: Symmetry Vs Harpe | S2: Model | T2: # Parts | U2: Parallel Time (seconds) | V2: Parallel Time (mins) | W2: Parallelobox (weaker) | X2: Parallelobox (stronger)
A3: 1053374 (25x) | B3: 5 | D3: =IF(NOT(ISBLANK(C3)), ROUND(C3/60,0), "") | F3: 1053374 (25x) | G3: 5 | H3: 137815 | I3: =IF(NOT(ISBLANK(H3)), ROUND(H3/60,0), "") -> 2297 | J3: =IF(I3="", IF(D3="", "Neither", "Parallelobox"), IF(D3="","Symmetry", I3-D3)) -> Symmetry | L3: 1053374 (25x) | M3: 5 | N3: 117941 | O3: =IF(NOT(ISBLANK(N3)), ROUND(N3/60,0), "") -> 1966 | P3: =IF(O3="", IF(D3="", "Neither", "Parallelobox"), IF(D3="","Harpe", O3-D3)) -> Harpe | Q3: =IF(O3="", IF(I3="", "Neither", "Symmetry"), IF(I3="","Harpe", O3-I3)) -> -331 | S3: 1053374 (25x) | T3: 28 | U3: 99761 | V3: =IF(NOT(ISBLANK(U3)), ROUND(U3/60,0), "") -> 1663 | W3: =V3-D6 -> 809 | X3: =V3-D7 -> 896
A4: 1053374 (25x) | B4: 10 | C4: 116930 | D4: =IF(NOT(ISBLANK(C4)), ROUND(C4/60,0), "") -> 1949 | F4: 1053374 (25x) | G4: 10 | H4: 84524 | I4: =IF(NOT(ISBLANK(H4)), ROUND(H4/60,0), "") -> 1409 | J4: =IF(I4="", IF(D4="", "Neither", "Parallelobox"), IF(D4="","Symmetry", I4-D4)) -> -540 | L4: 1053374 (25x) | M4: 10 | N4: 101626 | O4: =IF(NOT(ISBLANK(N4)), ROUND(N4/60,0), "") -> 1694 | P4: =IF(O4="", IF(D4="", "Neither", "Parallelobox"), IF(D4="","Harpe", O4-D4)) -> -255 | Q4: =IF(O4="", IF(I4="", "Neither", "Symmetry"), IF(I4="","Harpe", O4-I4)) -> 285 | S4: 41084 (10x) | T4: 31 | U4: 72499 | V4: =IF(NOT(ISBLANK(U4)), ROUND(U4/60,0), "") -> 1208 | W4: =V4-D17 -> 561 | X4: =V4-D18 -> 789
A5: 1053374 (25x) | B5: 15 | C5: 58579 | D5: =IF(NOT(ISBLANK(C5)), ROUND(C5/60,0), "") -> 976 | F5: 1053374 (25x) | G5: 15 | H5: 86725 | I5: =IF(NOT(ISBLANK(H5)), ROUND(H5/60,0), "") -> 1445 | J5: =IF(I5="", IF(D5="", "Neither", "Parallelobox"), IF(D5="","Symmetry", I5-D5)) -> 469 | L5: 1053374 (25x) | M5: 15 | N5: 69083 | O5: =IF(NOT(ISBLANK(N5)), ROUND(N5/60,0), "") -> 1151 | P5: =IF(O5="", IF(D5="", "Neither", "Parallelobox"), IF(D5="","Harpe", O5-D5)) -> 175 | Q5: =IF(O5="", IF(I5="", "Neither", "Symmetry"), IF(I5="","Harpe", O5-I5)) -> -294 | S5: 500094 (10x) | T5: 90 | U5: 109800 | V5: =IF(NOT(ISBLANK(U5)), ROUND(U5/60,0), "") -> 1830 | W5: =V5-D31 -> 1362 | X5: =V5-D32 -> 1494
A6: 1053374 (25x) | B6: 20 | C6: 51261 | D6: =IF(NOT(ISBLANK(C6)), ROUND(C6/60,0), "") -> 854 | F6: 1053374 (25x) | G6: 20 | H6: 48776 | I6: =IF(NOT(ISBLANK(H6)), ROUND(H6/60,0), "") -> 813 | J6: =IF(I6="", IF(D6="", "Neither", "Parallelobox"), IF(D6="","Symmetry", I6-D6)) -> -41 | L6: 1053374 (25x) | M6: 20 | N6: 53683 | O6: =IF(NOT(ISBLANK(N6)), ROUND(N6/60,0), "") -> 895 | P6: =IF(O6="", IF(D6="", "Neither", "Parallelobox"), IF(D6="","Harpe", O6-D6)) -> 41 | Q6: =IF(O6="", IF(I6="", "Neither", "Symmetry"), IF(I6="","Harpe", O6-I6)) -> 82 | S6: 51329 (4x) | T6: 19 | U6: 59571 | V6: =IF(NOT(ISBLANK(U6)), ROUND(U6/60,0), "") -> 993 | W6: Fail | X6: =V6-D36 -> 307
A7: 1053374 (25x) | B7: 30 | C7: 46007 | D7: =IF(NOT(ISBLANK(C7)), ROUND(C7/60,0), "") -> 767 | F7: 1053374 (25x) | G7: 30 | H7: 46599 | I7: =IF(NOT(ISBLANK(H7)), ROUND(H7/60,0), "") -> 777 | J7: =IF(I7="", IF(D7="", "Neither", "Parallelobox"), IF(D7="","Symmetry", I7-D7)) -> 10 | L7: 1053374 (25x) | M7: 30 | N7: 51066 | O7: =IF(NOT(ISBLANK(N7)), ROUND(N7/60,0), "") -> 851 | P7: =IF(O7="", IF(D7="", "Neither", "Parallelobox"), IF(D7="","Harpe", O7-D7)) -> 84 | Q7: =IF(O7="", IF(I7="", "Neither", "Symmetry"), IF(I7="","Harpe", O7-I7)) -> 74 | S7: 51329 (5x) | T7: 27 | U7: 121959 | V7: =IF(NOT(ISBLANK(U7)), ROUND(U7/60,0), "") -> 2033 | W7: Fail | X7: Fail
A8: 1053374 (25x) | B8: 40 | C8: 28869 | D8: =IF(NOT(ISBLANK(C8)), ROUND(C8/60,0), "") -> 481 | F8: 1053374 (25x) | G8: 40 | H8: 44404 | I8: =IF(NOT(ISBLANK(H8)), ROUND(H8/60,0), "") -> 740 | J8: =IF(I8="", IF(D8="", "Neither", "Parallelobox"), IF(D8="","Symmetry", I8-D8)) -> 259 | L8: 1053374 (25x) | M8: 40 | N8: 30762 | O8: =IF(NOT(ISBLANK(N8)), ROUND(N8/60,0), "") -> 513 | P8: =IF(O8="", IF(D8="", "Neither", "Parallelobox"), IF(D8="","Harpe", O8-D8)) -> 32 | Q8: =IF(O8="", IF(I8="", "Neither", "Symmetry"), IF(I8="","Harpe", O8-I8)) -> -227 | S8: 77951 (5x) | T8: 21 | U8: 70767 | V8: =IF(NOT(ISBLANK(U8)), ROUND(U8/60,0), "") -> 1179 | W8: =V8-D56 -> 839 | X8: =V8-D57 -> 897
A9: 1053374 (25x) | B9: 50 | C9: 25368 | D9: =IF(NOT(ISBLANK(C9)), ROUND(C9/60,0), "") -> 423 | F9: 1053374 (25x) | G9: 50 | H9: 34637 | I9: =IF(NOT(ISBLANK(H9)), ROUND(H9/60,0), "") -> 577 | J9: =IF(I9="", IF(D9="", "Neither", "Parallelobox"), IF(D9="","Symmetry", I9-D9)) -> 154 | L9: 1053374 (25x) | M9: 50 | N9: 40935 | O9: =IF(NOT(ISBLANK(N9)), ROUND(N9/60,0), "") -> 682 | P9: =IF(O9="", IF(D9="", "Neither", "Parallelobox"), IF(D9="","Harpe", O9-D9)) -> 259 | Q9: =IF(O9="", IF(I9="", "Neither", "Symmetry"), IF(I9="","Harpe", O9-I9)) -> 105 | S9: 78224 (5x) | T9: 21 | U9: 19383 | V9: =IF(NOT(ISBLANK(U9)), ROUND(U9/60,0), "") -> 323 | W9: =V9-D66 -> 183 | X9: =V9-D67 -> 222
A10: 1053374 (25x) | B10: 64 | C10: 23556 | D10: =IF(NOT(ISBLANK(C10)), ROUND(C10/60,0), "") -> 393 | F10: 1053374 (25x) | G10: 64 | H10: 38032 | I10: =IF(NOT(ISBLANK(H10)), ROUND(H10/60,0), "") -> 634 | J10: =IF(I10="", IF(D10="", "Neither", "Parallelobox"), IF(D10="","Symmetry", I10-D10)) -> 241 | L10: 1053374 (25x) | M10: 64 | N10: 27675 | O10: =IF(NOT(ISBLANK(N10)), ROUND(N10/60,0), "") -> 461 | P10: =IF(O10="", IF(D10="", "Neither", "Parallelobox"), IF(D10="","Harpe", O10-D10)) -> 68 | Q10: =IF(O10="", IF(I10="", "Neither", "Symmetry"), IF(I10="","Harpe", O10-I10)) -> -173 | S10: 797990 (5x) | T10: 20 | U10: 67141 | V10: =IF(NOT(ISBLANK(U10)), ROUND(U10/60,0), "") -> 1119 | W10: =V10-D76 -> 324 | X10: N/A
A11: 1053374 (25x) | B11: 82 | C11: 20806 | D11: =IF(NOT(ISBLANK(C11)), ROUND(C11/60,0), "") -> 347 | F11: 1053374 (25x) | G11: 82 | H11: 26544 | I11: =IF(NOT(ISBLANK(H11)), ROUND(H11/60,0), "") -> 442 | J11: =IF(I11="", IF(D11="", "Neither", "Parallelobox"), IF(D11="","Symmetry", I11-D11)) -> 95 | L11: 1053374 (25x) | M11: 82 | N11: 31010 | O11: =IF(NOT(ISBLANK(N11)), ROUND(N11/60,0), "") -> 517 | P11: =IF(O11="", IF(D11="", "Neither", "Parallelobox"), IF(D11="","Harpe", O11-D11)) -> 170 | Q11: =IF(O11="", IF(I11="", "Neither", "Symmetry"), IF(I11="","Harpe", O11-I11)) -> 75 | S11: 96457 (2x) | T11: 33 | U11: 2053155 | V11: =IF(NOT(ISBLANK(U11)), ROUND(U11/60,0), "") -> 34219 | W11: =V11-D87 -> 34170 | X11: =V11-D88 -> 34164
A12: 1053374 (25x) | B12: 100 | C12: 15955 | D12: =IF(NOT(ISBLANK(C12)), ROUND(C12/60,0), "") -> 266 | F12: 1053374 (25x) | G12: 100 | H12: 22349 | I12: =IF(NOT(ISBLANK(H12)), ROUND(H12/60,0), "") -> 372 | J12: =IF(I12="", IF(D12="", "Neither", "Parallelobox"), IF(D12="","Symmetry", I12-D12)) -> 106 | L12: 1053374 (25x) | M12: 100 | N12: 28677 | O12: =IF(NOT(ISBLANK(N12)), ROUND(N12/60,0), "") -> 478 | P12: =IF(O12="", IF(D12="", "Neither", "Parallelobox"), IF(D12="","Harpe", O12-D12)) -> 212 | Q12: =IF(O12="", IF(I12="", "Neither", "Symmetry"), IF(I12="","Harpe", O12-I12)) -> 106 | S12: 96457 (4x) | T12: 33 | U12: 15178792 | V12: =IF(NOT(ISBLANK(U12)), ROUND(U12/60,0), "") -> 252980 | W12: =V12-D97 -> 252733 | X12: =V12-D98 -> 252793
A13: 41084 (10x) | B13: 5 | D13: =IF(NOT(ISBLANK(C13)), ROUND(C13/60,0), "") | F13: 41084 (10x) | G13: 5 | H13: 109252 | I13: =IF(NOT(ISBLANK(H13)), ROUND(H13/60,0), "") -> 1821 | J13: =IF(I13="", IF(D13="", "Neither", "Parallelobox"), IF(D13="","Symmetry", I13-D13)) -> Symmetry | L13: 41084 (10x) | M13: 5 | N13: 160626 | O13: =IF(NOT(ISBLANK(N13)), ROUND(N13/60,0), "") -> 2677 | P13: =IF(O13="", IF(D13="", "Neither", "Parallelobox"), IF(D13="","Harpe", O13-D13)) -> Harpe | Q13: =IF(O13="", IF(I13="", "Neither", "Symmetry"), IF(I13="","Harpe", O13-I13)) -> 856 | S13: 3DBenchy (50cm) | T13: 31 | U13: 136650 | V13: =IF(NOT(ISBLANK(U13)), ROUND(U13/60,0), "") -> 2278 | W13: =V13-D107 -> 1504 | X13: =V13-D108 -> 1598
A14: 41084 (10x) | B14: 10 | C14: 98809 | D14: =IF(NOT(ISBLANK(C14)), ROUND(C14/60,0), "") -> 1647 | F14: 41084 (10x) | G14: 10 | H14: 79179 | I14: =IF(NOT(ISBLANK(H14)), ROUND(H14/60,0), "") -> 1320 | J14: =IF(I14="", IF(D14="", "Neither", "Parallelobox"), IF(D14="","Symmetry", I14-D14)) -> -327 | L14: 41084 (10x) | M14: 10 | N14: 101867 | O14: =IF(NOT(ISBLANK(N14)), ROUND(N14/60,0), "") -> 1698 | P14: =IF(O14="", IF(D14="", "Neither", "Parallelobox"), IF(D14="","Harpe", O14-D14)) -> 51 | Q14: =IF(O14="", IF(I14="", "Neither", "Symmetry"), IF(I14="","Harpe", O14-I14)) -> 378 | S14: 3DBenchy (70cm) | T14: 36 | U14: 442873 | V14: =IF(NOT(ISBLANK(U14)), ROUND(U14/60,0), "") -> 7381 | W14: Fail | X14: =V14-D120 -> 5595
A15: 41084 (10x) | B15: 15 | C15: 59586 | D15: =IF(NOT(ISBLANK(C15)), ROUND(C15/60,0), "") -> 993 | F15: 41084 (10x) | G15: 15 | H15: 60570 | I15: =IF(NOT(ISBLANK(H15)), ROUND(H15/60,0), "") -> 1010 | J15: =IF(I15="", IF(D15="", "Neither", "Parallelobox"), IF(D15="","Symmetry", I15-D15)) -> 17 | L15: 41084 (10x) | M15: 15 | N15: 88112 | O15: =IF(NOT(ISBLANK(N15)), ROUND(N15/60,0), "") -> 1469 | P15: =IF(O15="", IF(D15="", "Neither", "Parallelobox"), IF(D15="","Harpe", O15-D15)) -> 476 | Q15: =IF(O15="", IF(I15="", "Neither", "Symmetry"), IF(I15="","Harpe", O15-I15)) -> 459 | S15: Brain Left (4x) | T15: 52 | U15: 218729 | V15: =IF(NOT(ISBLANK(U15)), ROUND(U15/60,0), "") -> 3645 | W15: 1136 | X15: 831
A16: 41084 (10x) | B16: 20 | C16: 45696 | D16: =IF(NOT(ISBLANK(C16)), ROUND(C16/60,0), "") -> 762 | F16: 41084 (10x) | G16: 20 | H16: 52772 | I16: =IF(NOT(ISBLANK(H16)), ROUND(H16/60,0), "") -> 880 | J16: =IF(I16="", IF(D16="", "Neither", "Parallelobox"), IF(D16="","Symmetry", I16-D16)) -> 118 | L16: 41084 (10x) | M16: 20 | N16: 81285 | O16: =IF(NOT(ISBLANK(N16)), ROUND(N16/60,0), "") -> 1355 | P16: =IF(O16="", IF(D16="", "Neither", "Parallelobox"), IF(D16="","Harpe", O16-D16)) -> 593 | Q16: =IF(O16="", IF(I16="", "Neither", "Symmetry"), IF(I16="","Harpe", O16-I16)) -> 475 | S16: Large Building | T16: 14 | U16: 19756 | V16: =IF(NOT(ISBLANK(U16)), ROUND(U16/60,0), "") -> 329 | W16: =V16-D124 -> -43 | X16: =V16-D125 -> 70
A17: 41084 (10x) | B17: 30 | C17: 38843 | D17: =IF(NOT(ISBLANK(C17)), ROUND(C17/60,0), "") -> 647 | F17: 41084 (10x) | G17: 30 | H17: 50410 | I17: =IF(NOT(ISBLANK(H17)), ROUND(H17/60,0), "") -> 840 | J17: =IF(I17="", IF(D17="", "Neither", "Parallelobox"), IF(D17="","Symmetry", I17-D17)) -> 193 | L17: 41084 (10x) | M17: 30 | N17: 74128 | O17: =IF(NOT(ISBLANK(N17)), ROUND(N17/60,0), "") -> 1235 | P17: =IF(O17="", IF(D17="", "Neither", "Parallelobox"), IF(D17="","Harpe", O17-D17)) -> 588 | Q17: =IF(O17="", IF(I17="", "Neither", "Symmetry"), IF(I17="","Harpe", O17-I17)) -> 395 | S17: Large Building (2x) | T17: 15 | U17: 114368 | V17: =IF(NOT(ISBLANK(U17)), ROUND(U17/60,0), "") -> 1906 | W17: =V17-D135 -> 140 | X17: N/A
A18: 41084 (10x) | B18: 40 | C18: 25148 | D18: =IF(NOT(ISBLANK(C18)), ROUND(C18/60,0), "") -> 419 | F18: 41084 (10x) | G18: 40 | H18: 52916 | I18: =IF(NOT(ISBLANK(H18)), ROUND(H18/60,0), "") -> 882 | J18: =IF(I18="", IF(D18="", "Neither", "Parallelobox"), IF(D18="","Symmetry", I18-D18)) -> 463 | L18: 41084 (10x) | M18: 40 | P18: =IF(O18="", IF(D18="", "Neither", "Parallelobox"), IF(D18="","Harpe", O18-D18)) -> Parallelobox | Q18: =IF(O18="", IF(I18="", "Neither", "Symmetry"), IF(I18="","Harpe", O18-I18)) -> Symmetry | S18: Snail (50cm) | T18: 25 | U18: 61028 | V18: =IF(NOT(ISBLANK(U18)), ROUND(U18/60,0), "") -> 1017 | W18: =V18-D156 -> 178 | X18: =V18-D157 -> 492
A19: 41084 (10x) | B19: 50 | C19: 22999 | D19: =IF(NOT(ISBLANK(C19)), ROUND(C19/60,0), "") -> 383 | F19: 41084 (10x) | G19: 50 | H19: 35376 | I19: =IF(NOT(ISBLANK(H19)), ROUND(H19/60,0), "") -> 590 | J19: =IF(I19="", IF(D19="", "Neither", "Parallelobox"), IF(D19="","Symmetry", I19-D19)) -> 207 | L19: 41084 (10x) | M19: 50 | N19: 67182 | O19: =IF(NOT(ISBLANK(N19)), ROUND(N19/60,0), "") -> 1120 | P19: =IF(O19="", IF(D19="", "Neither", "Parallelobox"), IF(D19="","Harpe", O19-D19)) -> 737 | Q19: =IF(O19="", IF(I19="", "Neither", "Symmetry"), IF(I19="","Harpe", O19-I19)) -> 530 | S19: Stanford Bunny (2x) | T19: 24 | U19: 68406 | V19: =IF(NOT(ISBLANK(U19)), ROUND(U19/60,0), "") -> 1140 | W19: =V19-D166 -> 691 | X19: =V19-D167 -> 784
A20: 41084 (10x) | B20: 64 | C20: 20521 | D20: =IF(NOT(ISBLANK(C20)), ROUND(C20/60,0), "") -> 342 | F20: 41084 (10x) | G20: 64 | H20: 34394 | I20: =IF(NOT(ISBLANK(H20)), ROUND(H20/60,0), "") -> 573 | J20: =IF(I20="", IF(D20="", "Neither", "Parallelobox"), IF(D20="","Symmetry", I20-D20)) -> 231 | L20: 41084 (10x) | M20: 64 | N20: 56670 | O20: =IF(NOT(ISBLANK(N20)), ROUND(N20/60,0), "") -> 945 | P20: =IF(O20="", IF(D20="", "Neither", "Parallelobox"), IF(D20="","Harpe", O20-D20)) -> 603 | Q20: =IF(O20="", IF(I20="", "Neither", "Symmetry"), IF(I20="","Harpe", O20-I20)) -> 372 | S20: Utah Teapot | T20: 34 | U20: 5120752 | V20: =IF(NOT(ISBLANK(U20)), ROUND(U20/60,0), "") -> 85346 | W20: =V20-D177 -> 84680 | X20: =V20-D178 -> 84804
A21: 41084 (10x) | B21: 82 | C21: 19557 | D21: =IF(NOT(ISBLANK(C21)), ROUND(C21/60,0), "") -> 326 | F21: 41084 (10x) | G21: 82 | H21: 35319 | I21: =IF(NOT(ISBLANK(H21)), ROUND(H21/60,0), "") -> 589 | J21: =IF(I21="", IF(D21="", "Neither", "Parallelobox"), IF(D21="","Symmetry", I21-D21)) -> 263 | L21: 41084 (10x) | M21: 82 | N21: 61231 | O21: =IF(NOT(ISBLANK(N21)), ROUND(N21/60,0), "") -> 1021 | P21: =IF(O21="", IF(D21="", "Neither", "Parallelobox"), IF(D21="","Harpe", O21-D21)) -> 695 | Q21: =IF(O21="", IF(I21="", "Neither", "Symmetry"), IF(I21="","Harpe", O21-I21)) -> 432
A22: 41084 (10x) | B22: 100 | C22: 14139 | D22: =IF(NOT(ISBLANK(C22)), ROUND(C22/60,0), "") -> 236 | F22: 41084 (10x) | G22: 100 | H22: 24317 | I22: =IF(NOT(ISBLANK(H22)), ROUND(H22/60,0), "") -> 405 | J22: =IF(I22="", IF(D22="", "Neither", "Parallelobox"), IF(D22="","Symmetry", I22-D22)) -> 169 | L22: 41084 (10x) | M22: 100 | P22: =IF(O22="", IF(D22="", "Neither", "Parallelobox"), IF(D22="","Harpe", O22-D22)) -> Parallelobox | Q22: =IF(O22="", IF(I22="", "Neither", "Symmetry"), IF(I22="","Harpe", O22-I22)) -> Symmetry
A23: 500094 (10x) | B23: 5 | D23: =IF(NOT(ISBLANK(C23)), ROUND(C23/60,0), "") | F23: 500094 (10x) | G23: 5 | H23: 212635 | I23: =IF(NOT(ISBLANK(H23)), ROUND(H23/60,0), "") -> 3544 | J23: =IF(I23="", IF(D23="", "Neither", "Parallelobox"), IF(D23="","Symmetry", I23-D23)) -> Symmetry | L23: 500094 (10x) | M23: 5 | N23: 248227 | O23: =IF(NOT(ISBLANK(N23)), ROUND(N23/60,0), "") -> 4137 | P23: =IF(O23="", IF(D23="", "Neither", "Parallelobox"), IF(D23="","Harpe", O23-D23)) -> Harpe | Q23: =IF(O23="", IF(I23="", "Neither", "Symmetry"), IF(I23="","Harpe", O23-I23)) -> 593
A24: 500094 (10x) | B24: 10 | D24: =IF(NOT(ISBLANK(C24)), ROUND(C24/60,0), "") | F24: 500094 (10x) | G24: 10 | H24: 179372 | I24: =IF(NOT(ISBLANK(H24)), ROUND(H24/60,0), "") -> 2990 | J24: =IF(I24="", IF(D24="", "Neither", "Parallelobox"), IF(D24="","Symmetry", I24-D24)) -> Symmetry | L24: 500094 (10x) | M24: 10 | N24: 188753 | O24: =IF(NOT(ISBLANK(N24)), ROUND(N24/60,0), "") -> 3146 | P24: =IF(O24="", IF(D24="", "Neither", "Parallelobox"), IF(D24="","Harpe", O24-D24)) -> Harpe | Q24: =IF(O24="", IF(I24="", "Neither", "Symmetry"), IF(I24="","Harpe", O24-I24)) -> 156
A25: 500094 (10x) | B25: 15 | C25: 96129 | D25: =IF(NOT(ISBLANK(C25)), ROUND(C25/60,0), "") -> 1602 | F25: 500094 (10x) | G25: 15 | H25: 127536 | I25: =IF(NOT(ISBLANK(H25)), ROUND(H25/60,0), "") -> 2126 | J25: =IF(I25="", IF(D25="", "Neither", "Parallelobox"), IF(D25="","Symmetry", I25-D25)) -> 524 | L25: 500094 (10x) | M25: 15 | N25: 102606 | O25: =IF(NOT(ISBLANK(N25)), ROUND(N25/60,0), "") -> 1710 | P25: =IF(O25="", IF(D25="", "Neither", "Parallelobox"), IF(D25="","Harpe", O25-D25)) -> 108 | Q25: =IF(O25="", IF(I25="", "Neither", "Symmetry"), IF(I25="","Harpe", O25-I25)) -> -416
A26: 500094 (10x) | B26: 20 | C26: 78484 | D26: =IF(NOT(ISBLANK(C26)), ROUND(C26/60,0), "") -> 1308 | F26: 500094 (10x) | G26: 20 | H26: 88743 | I26: =IF(NOT(ISBLANK(H26)), ROUND(H26/60,0), "") -> 1479 | J26: =IF(I26="", IF(D26="", "Neither", "Parallelobox"), IF(D26="","Symmetry", I26-D26)) -> 171 | L26: 500094 (10x) | M26: 20 | N26: 93123 | O26: =IF(NOT(ISBLANK(N26)), ROUND(N26/60,0), "") -> 1552 | P26: =IF(O26="", IF(D26="", "Neither", "Parallelobox"), IF(D26="","Harpe", O26-D26)) -> 244 | Q26: =IF(O26="", IF(I26="", "Neither", "Symmetry"), IF(I26="","Harpe", O26-I26)) -> 73
A27: 500094 (10x) | B27: 30 | C27: 72884 | D27: =IF(NOT(ISBLANK(C27)), ROUND(C27/60,0), "") -> 1215 | F27: 500094 (10x) | G27: 30 | H27: 61254 | I27: =IF(NOT(ISBLANK(H27)), ROUND(H27/60,0), "") -> 1021 | J27: =IF(I27="", IF(D27="", "Neither", "Parallelobox"), IF(D27="","Symmetry", I27-D27)) -> -194 | L27: 500094 (10x) | M27: 30 | N27: 80031 | O27: =IF(NOT(ISBLANK(N27)), ROUND(N27/60,0), "") -> 1334 | P27: =IF(O27="", IF(D27="", "Neither", "Parallelobox"), IF(D27="","Harpe", O27-D27)) -> 119 | Q27: =IF(O27="", IF(I27="", "Neither", "Symmetry"), IF(I27="","Harpe", O27-I27)) -> 313
A28: 500094 (10x) | B28: 40 | C28: 63753 | D28: =IF(NOT(ISBLANK(C28)), ROUND(C28/60,0), "") -> 1063 | F28: 500094 (10x) | G28: 40 | H28: 56006 | I28: =IF(NOT(ISBLANK(H28)), ROUND(H28/60,0), "") -> 933 | J28: =IF(I28="", IF(D28="", "Neither", "Parallelobox"), IF(D28="","Symmetry", I28-D28)) -> -130 | L28: 500094 (10x) | M28: 40 | P28: =IF(O28="", IF(D28="", "Neither", "Parallelobox"), IF(D28="","Harpe", O28-D28)) -> Parallelobox | Q28: =IF(O28="", IF(I28="", "Neither", "Symmetry"), IF(I28="","Harpe", O28-I28)) -> Symmetry
A29: 500094 (10x) | B29: 50 | C29: 38641 | D29: =IF(NOT(ISBLANK(C29)), ROUND(C29/60,0), "") -> 644 | F29: 500094 (10x) | G29: 50 | H29: 44119 | I29: =IF(NOT(ISBLANK(H29)), ROUND(H29/60,0), "") -> 735 | J29: =IF(I29="", IF(D29="", "Neither", "Parallelobox"), IF(D29="","Symmetry", I29-D29)) -> 91 | L29: 500094 (10x) | M29: 50 | P29: =IF(O29="", IF(D29="", "Neither", "Parallelobox"), IF(D29="","Harpe", O29-D29)) -> Parallelobox | Q29: =IF(O29="", IF(I29="", "Neither", "Symmetry"), IF(I29="","Harpe", O29-I29)) -> Symmetry
A30: 500094 (10x) | B30: 64 | C30: 28973 | D30: =IF(NOT(ISBLANK(C30)), ROUND(C30/60,0), "") -> 483 | F30: 500094 (10x) | G30: 64 | H30: 37179 | I30: =IF(NOT(ISBLANK(H30)), ROUND(H30/60,0), "") -> 620 | J30: =IF(I30="", IF(D30="", "Neither", "Parallelobox"), IF(D30="","Symmetry", I30-D30)) -> 137 | L30: 500094 (10x) | M30: 64 | N30: 54819 | O30: =IF(NOT(ISBLANK(N30)), ROUND(N30/60,0), "") -> 914 | P30: =IF(O30="", IF(D30="", "Neither", "Parallelobox"), IF(D30="","Harpe", O30-D30)) -> 431 | Q30: =IF(O30="", IF(I30="", "Neither", "Symmetry"), IF(I30="","Harpe", O30-I30)) -> 294
A31: 500094 (10x) | B31: 82 | C31: 28103 | D31: =IF(NOT(ISBLANK(C31)), ROUND(C31/60,0), "") -> 468 | F31: 500094 (10x) | G31: 82 | H31: 38491 | I31: =IF(NOT(ISBLANK(H31)), ROUND(H31/60,0), "") -> 642 | J31: =IF(I31="", IF(D31="", "Neither", "Parallelobox"), IF(D31="","Symmetry", I31-D31)) -> 174 | L31: 500094 (10x) | M31: 82 | N31: 54380 | O31: =IF(NOT(ISBLANK(N31)), ROUND(N31/60,0), "") -> 906 | P31: =IF(O31="", IF(D31="", "Neither", "Parallelobox"), IF(D31="","Harpe", O31-D31)) -> 438 | Q31: =IF(O31="", IF(I31="", "Neither", "Symmetry"), IF(I31="","Harpe", O31-I31)) -> 264
A32: 500094 (10x) | B32: 100 | C32: 20135 | D32: =IF(NOT(ISBLANK(C32)), ROUND(C32/60,0), "") -> 336 | F32: 500094 (10x) | G32: 100 | H32: 45547 | I32: =IF(NOT(ISBLANK(H32)), ROUND(H32/60,0), "") -> 759 | J32: =IF(I32="", IF(D32="", "Neither", "Parallelobox"), IF(D32="","Symmetry", I32-D32)) -> 423 | L32: 500094 (10x) | M32: 100 | P32: =IF(O32="", IF(D32="", "Neither", "Parallelobox"), IF(D32="","Harpe", O32-D32)) -> Parallelobox | Q32: =IF(O32="", IF(I32="", "Neither", "Symmetry"), IF(I32="","Harpe", O32-I32)) -> Symmetry
A33: 51329 (4x) | B33: 5 | D33: =IF(NOT(ISBLANK(C33)), ROUND(C33/60,0), "") | F33: 51329 (4x) | G33: 5 | H33: 112932 | I33: =IF(NOT(ISBLANK(H33)), ROUND(H33/60,0), "") -> 1882 | J33: =IF(I33="", IF(D33="", "Neither", "Parallelobox"), IF(D33="","Symmetry", I33-D33)) -> Symmetry | L33: 51329 (4x) | M33: 5 | N33: 112098 | O33: =IF(NOT(ISBLANK(N33)), ROUND(N33/60,0), "") -> 1868 | P33: =IF(O33="", IF(D33="", "Neither", "Parallelobox"), IF(D33="","Harpe", O33-D33)) -> Harpe | Q33: =IF(O33="", IF(I33="", "Neither", "Symmetry"), IF(I33="","Harpe", O33-I33)) -> -14
A34: 51329 (4x) | B34: 10 | C34: 69029 | D34: =IF(NOT(ISBLANK(C34)), ROUND(C34/60,0), "") -> 1150 | F34: 51329 (4x) | G34: 10 | H34: 78057 | I34: =IF(NOT(ISBLANK(H34)), ROUND(H34/60,0), "") -> 1301 | J34: =IF(I34="", IF(D34="", "Neither", "Parallelobox"), IF(D34="","Symmetry", I34-D34)) -> 151 | L34: 51329 (4x) | M34: 10 | N34: 69506 | O34: =IF(NOT(ISBLANK(N34)), ROUND(N34/60,0), "") -> 1158 | P34: =IF(O34="", IF(D34="", "Neither", "Parallelobox"), IF(D34="","Harpe", O34-D34)) -> 8 | Q34: =IF(O34="", IF(I34="", "Neither", "Symmetry"), IF(I34="","Harpe", O34-I34)) -> -143
A35: 51329 (4x) | B35: 15 | D35: =IF(NOT(ISBLANK(C35)), ROUND(C35/60,0), "") | F35: 51329 (4x) | G35: 15 | H35: 49976 | I35: =IF(NOT(ISBLANK(H35)), ROUND(H35/60,0), "") -> 833 | J35: =IF(I35="", IF(D35="", "Neither", "Parallelobox"), IF(D35="","Symmetry", I35-D35)) -> Symmetry | L35: 51329 (4x) | M35: 15 | N35: 60970 | O35: =IF(NOT(ISBLANK(N35)), ROUND(N35/60,0), "") -> 1016 | P35: =IF(O35="", IF(D35="", "Neither", "Parallelobox"), IF(D35="","Harpe", O35-D35)) -> Harpe | Q35: =IF(O35="", IF(I35="", "Neither", "Symmetry"), IF(I35="","Harpe", O35-I35)) -> 183
A36: 51329 (4x) | B36: 20 | C36: 41130 | D36: =IF(NOT(ISBLANK(C36)), ROUND(C36/60,0), "") -> 686 | F36: 51329 (4x) | G36: 20 | H36: 46351 | I36: =IF(NOT(ISBLANK(H36)), ROUND(H36/60,0), "") -> 773 | J36: =IF(I36="", IF(D36="", "Neither", "Parallelobox"), IF(D36="","Symmetry", I36-D36)) -> 87 | L36: 51329 (4x) | M36: 20 | N36: 48068 | O36: =IF(NOT(ISBLANK(N36)), ROUND(N36/60,0), "") -> 801 | P36: =IF(O36="", IF(D36="", "Neither", "Parallelobox"), IF(D36="","Harpe", O36-D36)) -> 115 | Q36: =IF(O36="", IF(I36="", "Neither", "Symmetry"), IF(I36="","Harpe", O36-I36)) -> 28
A37: 51329 (4x) | B37: 30 | C37: 33168 | D37: =IF(NOT(ISBLANK(C37)), ROUND(C37/60,0), "") -> 553 | F37: 51329 (4x) | G37: 30 | H37: 35138 | I37: =IF(NOT(ISBLANK(H37)), ROUND(H37/60,0), "") -> 586 | J37: =IF(I37="", IF(D37="", "Neither", "Parallelobox"), IF(D37="","Symmetry", I37-D37)) -> 33 | L37: 51329 (4x) | M37: 30 | N37: 43599 | O37: =IF(NOT(ISBLANK(N37)), ROUND(N37/60,0), "") -> 727 | P37: =IF(O37="", IF(D37="", "Neither", "Parallelobox"), IF(D37="","Harpe", O37-D37)) -> 174 | Q37: =IF(O37="", IF(I37="", "Neither", "Symmetry"), IF(I37="","Harpe", O37-I37)) -> 141
A38: 51329 (4x) | B38: 40 | C38: 26222 | D38: =IF(NOT(ISBLANK(C38)), ROUND(C38/60,0), "") -> 437 | F38: 51329 (4x) | G38: 40 | H38: 34672 | I38: =IF(NOT(ISBLANK(H38)), ROUND(H38/60,0), "") -> 578 | J38: =IF(I38="", IF(D38="", "Neither", "Parallelobox"), IF(D38="","Symmetry", I38-D38)) -> 141 | L38: 51329 (4x) | M38: 40 | N38: 30652 | O38: =IF(NOT(ISBLANK(N38)), ROUND(N38/60,0), "") -> 511 | P38: =IF(O38="", IF(D38="", "Neither", "Parallelobox"), IF(D38="","Harpe", O38-D38)) -> 74 | Q38: =IF(O38="", IF(I38="", "Neither", "Symmetry"), IF(I38="","Harpe", O38-I38)) -> -67
A39: 51329 (4x) | B39: 50 | C39: 19630 | D39: =IF(NOT(ISBLANK(C39)), ROUND(C39/60,0), "") -> 327 | F39: 51329 (4x) | G39: 50 | H39: 27739 | I39: =IF(NOT(ISBLANK(H39)), ROUND(H39/60,0), "") -> 462 | J39: =IF(I39="", IF(D39="", "Neither", "Parallelobox"), IF(D39="","Symmetry", I39-D39)) -> 135 | L39: 51329 (4x) | M39: 50 | N39: 41421 | O39: =IF(NOT(ISBLANK(N39)), ROUND(N39/60,0), "") -> 690 | P39: =IF(O39="", IF(D39="", "Neither", "Parallelobox"), IF(D39="","Harpe", O39-D39)) -> 363 | Q39: =IF(O39="", IF(I39="", "Neither", "Symmetry"), IF(I39="","Harpe", O39-I39)) -> 228
A40: 51329 (4x) | B40: 64 | C40: 16549 | D40: =IF(NOT(ISBLANK(C40)), ROUND(C40/60,0), "") -> 276 | F40: 51329 (4x) | G40: 64 | H40: 25002 | I40: =IF(NOT(ISBLANK(H40)), ROUND(H40/60,0), "") -> 417 | J40: =IF(I40="", IF(D40="", "Neither", "Parallelobox"), IF(D40="","Symmetry", I40-D40)) -> 141 | L40: 51329 (4x) | M40: 64 | N40: 30401 | O40: =IF(NOT(ISBLANK(N40)), ROUND(N40/60,0), "") -> 507 | P40: =IF(O40="", IF(D40="", "Neither", "Parallelobox"), IF(D40="","Harpe", O40-D40)) -> 231 | Q40: =IF(O40="", IF(I40="", "Neither", "Symmetry"), IF(I40="","Harpe", O40-I40)) -> 90
...

Sheet Failure Matrix
A2: Model | B2: # Printers | D2: vs Symmetry | E2: vs Harpe | H2: Model | I2: Printer Quantity | T2: Model | U2: Printer Quantity
A3: 1053374 (25x) | B3: 5 | D3: Symmetry | E3: Harpe | I3: 5 | J3: 10 | K3: 15 | L3: 20 | M3: 30 | N3: 40 | O3: 50 | P3: 64 | Q3: 82 | R3: 100 | U3: 5 | V3: 10 | W3: 15 | X3: 20 | Y3: 30 | Z3: 40 | AA3: 50 | AB3: 64 | AC3: 82 | AD3: 100
A4: 1053374 (25x) | B4: 10 | C4: 2056 | H4: Strange Washer | T4: Strange Washer
A5: 1053374 (25x) | B5: 15 | C5: 1016 | H5: Mini Refinery | T5: Mini Refinery
A6: 1053374 (25x) | B6: 20 | C6: 755 | H6: Sparse Lattice | T6: Sparse Lattice
A7: 1053374 (25x) | B7: 30 | C7: 645 | H7: Unusual Vase (4x) | T7: Unusual Vase (4x)
A8: 1053374 (25x) | B8: 40 | C8: 500 | H8: Unusual Vase (5x) | T8: Unusual Vase (5x)
A9: 1053374 (25x) | B9: 50 | C9: 405 | H9: Side Plate | T9: Side Plate
A10: 1053374 (25x) | B10: 64 | C10: 389 | H10: Hole Pipe | T10: Hole Pipe
A11: 1053374 (25x) | B11: 82 | C11: 363 | H11: Trousers | T11: Trousers
A12: 1053374 (25x) | B12: 100 | C12: 278 | H12: Nighthawk (2x) | T12: Nighthawk (2x)
A13: 41084 (10x) | B13: 5 | D13: Symmetry | E13: Harpe | H13: Nighthawk (4x) | T13: Nighthawk (4x)
A14: 41084 (10x) | B14: 10 | C14: 1594 | H14: 3DBenchy (50cm) | T14: 3DBenchy (50cm)
A15: 41084 (10x) | B15: 15 | C15: 1115 | H15: 3DBenchy (70cm) | T15: 3DBenchy (70cm)
A16: 41084 (10x) | B16: 20 | C16: 797 | H16: Brain Left (4x) | T16: Brain Left (4x)
A17: 41084 (10x) | B17: 30 | C17: 610 | H17: Large Building | T17: Large Building
A18: 41084 (10x) | B18: 40 | C18: 487 | E18: Parallelobox | H18: Large Building (2x) | T18: Large Building (2x)
A19: 41084 (10x) | B19: 50 | C19: 424 | H19: Snail | T19: Snail
A20: 41084 (10x) | B20: 64 | C20: 374 | H20: Stanford Bunny | T20: Stanford Bunny
A21: 41084 (10x) | B21: 82 | C21: 328 | H21: Utah Teapot | T21: Utah Teapot
A22: 41084 (10x) | B22: 100 | C22: 266 | E22: Parallelobox
A23: 500094 (10x) | B23: 5 | D23: Symmetry | E23: Harpe
A24: 500094 (10x) | B24: 10 | D24: Symmetry | E24: Harpe
A25: 500094 (10x) | B25: 15 | C25: 1746
A26: 500094 (10x) | B26: 20 | C26: 1579
A27: 500094 (10x) | B27: 30 | C27: 1277
A28: 500094 (10x) | B28: 40 | C28: 979 | E28: Parallelobox
A29: 500094 (10x) | B29: 50 | C29: 707 | E29: Parallelobox
A30: 500094 (10x) | B30: 64 | C30: 529
A31: 500094 (10x) | B31: 82 | C31: 493
A32: 500094 (10x) | B32: 100 | C32: 440 | E32: Parallelobox
A33: 51329 (4x) | B33: 5 | D33: Symmetry | E33: Harpe
A34: 51329 (4x) | B34: 10 | C34: 1157
A35: 51329 (4x) | B35: 15 | C35: 833 | E35: Harpe
A36: 51329 (4x) | B36: 20 | C36: 670
A37: 51329 (4x) | B37: 30 | C37: 506
A38: 51329 (4x) | B38: 40 | C38: 405
A39: 51329 (4x) | B39: 50 | C39: 336
A40: 51329 (4x) | B40: 64 | C40: 271
A41: 51329 (4x) | B41: 82 | C41: 235
...

Sheet Repeats
A1: Parallelobox | C1: 632456723 | E1: 632456723 (No Symmetry) | G1: 632456723 (Low Granularity) | I1: 632456723 (More Samples) | K1: 102370435 | M1: 102370435 (No Symmetry) | O1: 102370435 (Low Granularity) | Q1: 102370435 (More Samples) | S1: 914023457 | U1: 914023457 (No Symmetry) | W1: 914023457 (Low Granularity) | Z1: 914023457 (More Samples)
A2: Model | B2: # Printers | C2: Parallel Time (seconds) | D2: Parallel Time (mins) | E2: Parallel Time (seconds) | F2: Parallel Time (mins) | G2: Parallel Time (seconds) | H2: Parallel Time (mins) | I2: Parallel Time (seconds) | J2: Parallel Time (mins) | K2: Parallel Time (seconds) | L2: Parallel Time (mins) | M2: Parallel Time (seconds) | N2: Parallel Time (mins) | O2: Parallel Time (seconds) | P2: Parallel Time (mins) | Q2: Parallel Time (seconds) | R2: Parallel Time (mins) | S2: Parallel Time (seconds) | T2: Parallel Time (mins) | U2: Parallel Time (seconds) | V2: Parallel Time (mins) | W2: Parallel Time (seconds) | X2: Parallel Time (mins) | Z2: Parallel Time (seconds) | AA2: Parallel Time (mins)
A3: 1053374 (25x) | B3: 5 | D3: =IF(NOT(ISBLANK(C3)), ROUND(C3/60,0), "") | F3: =IF(NOT(ISBLANK(E3)), ROUND(E3/60,0), "") | H3: =IF(NOT(ISBLANK(G3)), ROUND(G3/60,0), "") | L3: =IF(NOT(ISBLANK(K3)), ROUND(K3/60,0), "") | N3: =IF(NOT(ISBLANK(M3)), ROUND(M3/60,0), "") | P3: =IF(NOT(ISBLANK(O3)), ROUND(O3/60,0), "") | R3: =IF(NOT(ISBLANK(Q3)), ROUND(Q3/60,0), "") | T3: =IF(NOT(ISBLANK(S3)), ROUND(S3/60,0), "") | U3: 205336 | V3: =IF(NOT(ISBLANK(U3)), ROUND(U3/60,0), "") -> 3422 | X3: =IF(NOT(ISBLANK(W3)), ROUND(W3/60,0), "") | AA3: =IF(NOT(ISBLANK(Z3)), ROUND(Z3/60,0), "") | AC3: 1053374 (25x)
A4: 1053374 (25x) | B4: 10 | C4: 116930 | D4: =IF(NOT(ISBLANK(C4)), ROUND(C4/60,0), "") -> 1949 | E4: 91821 | F4: =IF(NOT(ISBLANK(E4)), ROUND(E4/60,0), "") -> 1530 | G4: 112091 | H4: =IF(NOT(ISBLANK(G4)), ROUND(G4/60,0), "") -> 1868 | K4: 140122 | L4: =IF(NOT(ISBLANK(K4)), ROUND(K4/60,0), "") -> 2335 | M4: 74746 | N4: =IF(NOT(ISBLANK(M4)), ROUND(M4/60,0), "") -> 1246 | O4: 113169 | P4: =IF(NOT(ISBLANK(O4)), ROUND(O4/60,0), "") -> 1886 | Q4: 140121 | R4: =IF(NOT(ISBLANK(Q4)), ROUND(Q4/60,0), "") -> 2335 | S4: 113017 | T4: =IF(NOT(ISBLANK(S4)), ROUND(S4/60,0), "") -> 1884 | U4: 106077 | V4: =IF(NOT(ISBLANK(U4)), ROUND(U4/60,0), "") -> 1768 | W4: 104643 | X4: =IF(NOT(ISBLANK(W4)), ROUND(W4/60,0), "") -> 1744 | Z4: 90374 | AA4: =IF(NOT(ISBLANK(Z4)), ROUND(Z4/60,0), "") -> 1506 | AC4: 1053374 (25x)
A5: 1053374 (25x) | B5: 15 | C5: 58579 | D5: =IF(NOT(ISBLANK(C5)), ROUND(C5/60,0), "") -> 976 | E5: 67329 | F5: =IF(NOT(ISBLANK(E5)), ROUND(E5/60,0), "") -> 1122 | G5: 78706 | H5: =IF(NOT(ISBLANK(G5)), ROUND(G5/60,0), "") -> 1312 | K5: 63466 | L5: =IF(NOT(ISBLANK(K5)), ROUND(K5/60,0), "") -> 1058 | M5: 59347 | N5: =IF(NOT(ISBLANK(M5)), ROUND(M5/60,0), "") -> 989 | O5: 57281 | P5: =IF(NOT(ISBLANK(O5)), ROUND(O5/60,0), "") -> 955 | Q5: 68737 | R5: =IF(NOT(ISBLANK(Q5)), ROUND(Q5/60,0), "") -> 1146 | S5: 60867 | T5: =IF(NOT(ISBLANK(S5)), ROUND(S5/60,0), "") -> 1014 | U5: 60040 | V5: =IF(NOT(ISBLANK(U5)), ROUND(U5/60,0), "") -> 1001 | W5: 59702 | X5: =IF(NOT(ISBLANK(W5)), ROUND(W5/60,0), "") -> 995 | Z5: 59497 | AA5: =IF(NOT(ISBLANK(Z5)), ROUND(Z5/60,0), "") -> 992 | AC5: 1053374 (25x)
A6: 1053374 (25x) | B6: 20 | C6: 51261 | D6: =IF(NOT(ISBLANK(C6)), ROUND(C6/60,0), "") -> 854 | E6: 41673 | F6: =IF(NOT(ISBLANK(E6)), ROUND(E6/60,0), "") -> 695 | G6: 50224 | H6: =IF(NOT(ISBLANK(G6)), ROUND(G6/60,0), "") -> 837 | K6: 42195 | L6: =IF(NOT(ISBLANK(K6)), ROUND(K6/60,0), "") -> 703 | M6: 44492 | N6: =IF(NOT(ISBLANK(M6)), ROUND(M6/60,0), "") -> 742 | O6: 51782 | P6: =IF(NOT(ISBLANK(O6)), ROUND(O6/60,0), "") -> 863 | Q6: 42195 | R6: =IF(NOT(ISBLANK(Q6)), ROUND(Q6/60,0), "") -> 703 | S6: 42466 | T6: =IF(NOT(ISBLANK(S6)), ROUND(S6/60,0), "") -> 708 | U6: 45609 | V6: =IF(NOT(ISBLANK(U6)), ROUND(U6/60,0), "") -> 760 | W6: 35633 | X6: =IF(NOT(ISBLANK(W6)), ROUND(W6/60,0), "") -> 594 | Z6: 42465 | AA6: =IF(NOT(ISBLANK(Z6)), ROUND(Z6/60,0), "") -> 708 | AC6: 1053374 (25x)
A7: 1053374 (25x) | B7: 30 | C7: 46007 | D7: =IF(NOT(ISBLANK(C7)), ROUND(C7/60,0), "") -> 767 | E7: 43403 | F7: =IF(NOT(ISBLANK(E7)), ROUND(E7/60,0), "") -> 723 | G7: 32428 | H7: =IF(NOT(ISBLANK(G7)), ROUND(G7/60,0), "") -> 540 | K7: 34734 | L7: =IF(NOT(ISBLANK(K7)), ROUND(K7/60,0), "") -> 579 | M7: 30535 | N7: =IF(NOT(ISBLANK(M7)), ROUND(M7/60,0), "") -> 509 | O7: 35306 | P7: =IF(NOT(ISBLANK(O7)), ROUND(O7/60,0), "") -> 588 | Q7: 34734 | R7: =IF(NOT(ISBLANK(Q7)), ROUND(Q7/60,0), "") -> 579 | S7: 35279 | T7: =IF(NOT(ISBLANK(S7)), ROUND(S7/60,0), "") -> 588 | U7: 30141 | V7: =IF(NOT(ISBLANK(U7)), ROUND(U7/60,0), "") -> 502 | W7: 28715 | X7: =IF(NOT(ISBLANK(W7)), ROUND(W7/60,0), "") -> 479 | Z7: 32084 | AA7: =IF(NOT(ISBLANK(Z7)), ROUND(Z7/60,0), "") -> 535 | AC7: 1053374 (25x)
A8: 1053374 (25x) | B8: 40 | C8: 28869 | D8: =IF(NOT(ISBLANK(C8)), ROUND(C8/60,0), "") -> 481 | E8: 30396 | F8: =IF(NOT(ISBLANK(E8)), ROUND(E8/60,0), "") -> 507 | G8: 26079 | H8: =IF(NOT(ISBLANK(G8)), ROUND(G8/60,0), "") -> 435 | K8: 32994 | L8: =IF(NOT(ISBLANK(K8)), ROUND(K8/60,0), "") -> 550 | M8: 27710 | N8: =IF(NOT(ISBLANK(M8)), ROUND(M8/60,0), "") -> 462 | O8: 27172 | P8: =IF(NOT(ISBLANK(O8)), ROUND(O8/60,0), "") -> 453 | Q8: 33634 | R8: =IF(NOT(ISBLANK(Q8)), ROUND(Q8/60,0), "") -> 561 | S8: 28159 | T8: =IF(NOT(ISBLANK(S8)), ROUND(S8/60,0), "") -> 469 | U8: 23966 | V8: =IF(NOT(ISBLANK(U8)), ROUND(U8/60,0), "") -> 399 | W8: 24257 | X8: =IF(NOT(ISBLANK(W8)), ROUND(W8/60,0), "") -> 404 | Z8: 28159 | AA8: =IF(NOT(ISBLANK(Z8)), ROUND(Z8/60,0), "") -> 469 | AC8: 1053374 (25x)
A9: 1053374 (25x) | B9: 50 | C9: 25368 | D9: =IF(NOT(ISBLANK(C9)), ROUND(C9/60,0), "") -> 423 | E9: 28582 | F9: =IF(NOT(ISBLANK(E9)), ROUND(E9/60,0), "") -> 476 | G9: 22809 | H9: =IF(NOT(ISBLANK(G9)), ROUND(G9/60,0), "") -> 380 | K9: 25898 | L9: =IF(NOT(ISBLANK(K9)), ROUND(K9/60,0), "") -> 432 | M9: 24305 | N9: =IF(NOT(ISBLANK(M9)), ROUND(M9/60,0), "") -> 405 | O9: 24355 | P9: =IF(NOT(ISBLANK(O9)), ROUND(O9/60,0), "") -> 406 | Q9: 27846 | R9: =IF(NOT(ISBLANK(Q9)), ROUND(Q9/60,0), "") -> 464 | S9: 21684 | T9: =IF(NOT(ISBLANK(S9)), ROUND(S9/60,0), "") -> 361 | U9: 23166 | V9: =IF(NOT(ISBLANK(U9)), ROUND(U9/60,0), "") -> 386 | W9: 19108 | X9: =IF(NOT(ISBLANK(W9)), ROUND(W9/60,0), "") -> 318 | Z9: 22175 | AA9: =IF(NOT(ISBLANK(Z9)), ROUND(Z9/60,0), "") -> 370 | AC9: 1053374 (25x)
A10: 1053374 (25x) | B10: 64 | C10: 23556 | D10: =IF(NOT(ISBLANK(C10)), ROUND(C10/60,0), "") -> 393 | E10: 21309 | F10: =IF(NOT(ISBLANK(E10)), ROUND(E10/60,0), "") -> 355 | G10: 21406 | H10: =IF(NOT(ISBLANK(G10)), ROUND(G10/60,0), "") -> 357 | K10: 22970 | L10: =IF(NOT(ISBLANK(K10)), ROUND(K10/60,0), "") -> 383 | M10: 19866 | N10: =IF(NOT(ISBLANK(M10)), ROUND(M10/60,0), "") -> 331 | O10: 27293 | P10: =IF(NOT(ISBLANK(O10)), ROUND(O10/60,0), "") -> 455 | Q10: 21354 | R10: =IF(NOT(ISBLANK(Q10)), ROUND(Q10/60,0), "") -> 356 | S10: 23375 | T10: =IF(NOT(ISBLANK(S10)), ROUND(S10/60,0), "") -> 390 | U10: 20143 | V10: =IF(NOT(ISBLANK(U10)), ROUND(U10/60,0), "") -> 336 | W10: 17487 | X10: =IF(NOT(ISBLANK(W10)), ROUND(W10/60,0), "") -> 291 | Z10: 18923 | AA10: =IF(NOT(ISBLANK(Z10)), ROUND(Z10/60,0), "") -> 315 | AC10: 1053374 (25x)
A11: 1053374 (25x) | B11: 82 | C11: 20806 | D11: =IF(NOT(ISBLANK(C11)), ROUND(C11/60,0), "") -> 347 | E11: 20671 | F11: =IF(NOT(ISBLANK(E11)), ROUND(E11/60,0), "") -> 345 | G11: 17931 | H11: =IF(NOT(ISBLANK(G11)), ROUND(G11/60,0), "") -> 299 | K11: 23530 | L11: =IF(NOT(ISBLANK(K11)), ROUND(K11/60,0), "") -> 392 | M11: 16605 | N11: =IF(NOT(ISBLANK(M11)), ROUND(M11/60,0), "") -> 277 | O11: 17669 | P11: =IF(NOT(ISBLANK(O11)), ROUND(O11/60,0), "") -> 294 | Q11: 21503 | R11: =IF(NOT(ISBLANK(Q11)), ROUND(Q11/60,0), "") -> 358 | S11: 21073 | T11: =IF(NOT(ISBLANK(S11)), ROUND(S11/60,0), "") -> 351 | U11: 17443 | V11: =IF(NOT(ISBLANK(U11)), ROUND(U11/60,0), "") -> 291 | W11: 17045 | X11: =IF(NOT(ISBLANK(W11)), ROUND(W11/60,0), "") -> 284 | Z11: 19239 | AA11: =IF(NOT(ISBLANK(Z11)), ROUND(Z11/60,0), "") -> 321 | AC11: 1053374 (25x)
A12: 1053374 (25x) | B12: 100 | C12: 15955 | D12: =IF(NOT(ISBLANK(C12)), ROUND(C12/60,0), "") -> 266 | E12: 15504 | F12: =IF(NOT(ISBLANK(E12)), ROUND(E12/60,0), "") -> 258 | G12: 16764 | H12: =IF(NOT(ISBLANK(G12)), ROUND(G12/60,0), "") -> 279 | K12: 16770 | L12: =IF(NOT(ISBLANK(K12)), ROUND(K12/60,0), "") -> 280 | M12: 18752 | N12: =IF(NOT(ISBLANK(M12)), ROUND(M12/60,0), "") -> 313 | P12: =IF(NOT(ISBLANK(O12)), ROUND(O12/60,0), "") | Q12: 16223 | R12: =IF(NOT(ISBLANK(Q12)), ROUND(Q12/60,0), "") -> 270 | S12: 17330 | T12: =IF(NOT(ISBLANK(S12)), ROUND(S12/60,0), "") -> 289 | U12: 13874 | V12: =IF(NOT(ISBLANK(U12)), ROUND(U12/60,0), "") -> 231 | X12: =IF(NOT(ISBLANK(W12)), ROUND(W12/60,0), "") | Z12: 16740 | AA12: =IF(NOT(ISBLANK(Z12)), ROUND(Z12/60,0), "") -> 279 | AC12: 1053374 (25x)
A13: 41084 (10x) | B13: 5 | D13: =IF(NOT(ISBLANK(C13)), ROUND(C13/60,0), "") | F13: =IF(NOT(ISBLANK(E13)), ROUND(E13/60,0), "") | H13: =IF(NOT(ISBLANK(G13)), ROUND(G13/60,0), "") | L13: =IF(NOT(ISBLANK(K13)), ROUND(K13/60,0), "") | N13: =IF(NOT(ISBLANK(M13)), ROUND(M13/60,0), "") | P13: =IF(NOT(ISBLANK(O13)), ROUND(O13/60,0), "") | R13: =IF(NOT(ISBLANK(Q13)), ROUND(Q13/60,0), "") | T13: =IF(NOT(ISBLANK(S13)), ROUND(S13/60,0), "") | V13: =IF(NOT(ISBLANK(U13)), ROUND(U13/60,0), "") | W13: 107437 | X13: =IF(NOT(ISBLANK(W13)), ROUND(W13/60,0), "") -> 1791 | AA13: =IF(NOT(ISBLANK(Z13)), ROUND(Z13/60,0), "") | AC13: 41084 (10x)
A14: 41084 (10x) | B14: 10 | C14: 98809 | D14: =IF(NOT(ISBLANK(C14)), ROUND(C14/60,0), "") -> 1647 | E14: 77472 | F14: =IF(NOT(ISBLANK(E14)), ROUND(E14/60,0), "") -> 1291 | G14: 81195 | H14: =IF(NOT(ISBLANK(G14)), ROUND(G14/60,0), "") -> 1353 | K14: 83636 | L14: =IF(NOT(ISBLANK(K14)), ROUND(K14/60,0), "") -> 1394 | N14: =IF(NOT(ISBLANK(M14)), ROUND(M14/60,0), "") | O14: 83504 | P14: =IF(NOT(ISBLANK(O14)), ROUND(O14/60,0), "") -> 1392 | Q14: 83636 | R14: =IF(NOT(ISBLANK(Q14)), ROUND(Q14/60,0), "") -> 1394 | S14: 104370 | T14: =IF(NOT(ISBLANK(S14)), ROUND(S14/60,0), "") -> 1740 | U14: 87642 | V14: =IF(NOT(ISBLANK(U14)), ROUND(U14/60,0), "") -> 1461 | W14: 84126 | X14: =IF(NOT(ISBLANK(W14)), ROUND(W14/60,0), "") -> 1402 | AA14: =IF(NOT(ISBLANK(Z14)), ROUND(Z14/60,0), "") | AC14: 41084 (10x)
A15: 41084 (10x) | B15: 15 | C15: 59586 | D15: =IF(NOT(ISBLANK(C15)), ROUND(C15/60,0), "") -> 993 | E15: 60745 | F15: =IF(NOT(ISBLANK(E15)), ROUND(E15/60,0), "") -> 1012 | G15: 67922 | H15: =IF(NOT(ISBLANK(G15)), ROUND(G15/60,0), "") -> 1132 | K15: 67994 | L15: =IF(NOT(ISBLANK(K15)), ROUND(K15/60,0), "") -> 1133 | M15: 54160 | N15: =IF(NOT(ISBLANK(M15)), ROUND(M15/60,0), "") -> 903 | O15: 65764 | P15: =IF(NOT(ISBLANK(O15)), ROUND(O15/60,0), "") -> 1096 | Q15: 59205 | R15: =IF(NOT(ISBLANK(Q15)), ROUND(Q15/60,0), "") -> 987 | S15: 73073 | T15: =IF(NOT(ISBLANK(S15)), ROUND(S15/60,0), "") -> 1218 | U15: 58746 | V15: =IF(NOT(ISBLANK(U15)), ROUND(U15/60,0), "") -> 979 | W15: 55409 | X15: =IF(NOT(ISBLANK(W15)), ROUND(W15/60,0), "") -> 923 | Z15: 76155 | AA15: =IF(NOT(ISBLANK(Z15)), ROUND(Z15/60,0), "") -> 1269 | AC15: 41084 (10x)
A16: 41084 (10x) | B16: 20 | C16: 45696 | D16: =IF(NOT(ISBLANK(C16)), ROUND(C16/60,0), "") -> 762 | E16: 59074 | F16: =IF(NOT(ISBLANK(E16)), ROUND(E16/60,0), "") -> 985 | G16: 57826 | H16: =IF(NOT(ISBLANK(G16)), ROUND(G16/60,0), "") -> 964 | K16: 51218 | L16: =IF(NOT(ISBLANK(K16)), ROUND(K16/60,0), "") -> 854 | M16: 48131 | N16: =IF(NOT(ISBLANK(M16)), ROUND(M16/60,0), "") -> 802 | O16: 42673 | P16: =IF(NOT(ISBLANK(O16)), ROUND(O16/60,0), "") -> 711 | Q16: 51218 | R16: =IF(NOT(ISBLANK(Q16)), ROUND(Q16/60,0), "") -> 854 | S16: 46539 | T16: =IF(NOT(ISBLANK(S16)), ROUND(S16/60,0), "") -> 776 | U16: 50926 | V16: =IF(NOT(ISBLANK(U16)), ROUND(U16/60,0), "") -> 849 | W16: 36369 | X16: =IF(NOT(ISBLANK(W16)), ROUND(W16/60,0), "") -> 606 | Z16: 46136 | AA16: =IF(NOT(ISBLANK(Z16)), ROUND(Z16/60,0), "") -> 769 | AC16: 41084 (10x)
A17: 41084 (10x) | B17: 30 | C17: 38843 | D17: =IF(NOT(ISBLANK(C17)), ROUND(C17/60,0), "") -> 647 | E17: 31958 | F17: =IF(NOT(ISBLANK(E17)), ROUND(E17/60,0), "") -> 533 | G17: 39022 | H17: =IF(NOT(ISBLANK(G17)), ROUND(G17/60,0), "") -> 650 | K17: 33306 | L17: =IF(NOT(ISBLANK(K17)), ROUND(K17/60,0), "") -> 555 | M17: 34914 | N17: =IF(NOT(ISBLANK(M17)), ROUND(M17/60,0), "") -> 582 | O17: 37157 | P17: =IF(NOT(ISBLANK(O17)), ROUND(O17/60,0), "") -> 619 | Q17: 33306 | R17: =IF(NOT(ISBLANK(Q17)), ROUND(Q17/60,0), "") -> 555 | S17: 37755 | T17: =IF(NOT(ISBLANK(S17)), ROUND(S17/60,0), "") -> 629 | U17: 32153 | V17: =IF(NOT(ISBLANK(U17)), ROUND(U17/60,0), "") -> 536 | W17: 31408 | X17: =IF(NOT(ISBLANK(W17)), ROUND(W17/60,0), "") -> 523 | Z17: 37756 | AA17: =IF(NOT(ISBLANK(Z17)), ROUND(Z17/60,0), "") -> 629 | AC17: 41084 (10x)
A18: 41084 (10x) | B18: 40 | C18: 25148 | D18: =IF(NOT(ISBLANK(C18)), ROUND(C18/60,0), "") -> 419 | F18: =IF(NOT(ISBLANK(E18)), ROUND(E18/60,0), "") | G18: 28685 | H18: =IF(NOT(ISBLANK(G18)), ROUND(G18/60,0), "") -> 478 | K18: 33456 | L18: =IF(NOT(ISBLANK(K18)), ROUND(K18/60,0), "") -> 558 | M18: 25708 | N18: =IF(NOT(ISBLANK(M18)), ROUND(M18/60,0), "") -> 428 | O18: 28399 | P18: =IF(NOT(ISBLANK(O18)), ROUND(O18/60,0), "") -> 473 | Q18: 27090 | R18: =IF(NOT(ISBLANK(Q18)), ROUND(Q18/60,0), "") -> 452 | S18: 29004 | T18: =IF(NOT(ISBLANK(S18)), ROUND(S18/60,0), "") -> 483 | U18: 27681 | V18: =IF(NOT(ISBLANK(U18)), ROUND(U18/60,0), "") -> 461 | W18: 26445 | X18: =IF(NOT(ISBLANK(W18)), ROUND(W18/60,0), "") -> 441 | Z18: 29364 | AA18: =IF(NOT(ISBLANK(Z18)), ROUND(Z18/60,0), "") -> 489 | AC18: 41084 (10x)
A19: 41084 (10x) | B19: 50 | C19: 22999 | D19: =IF(NOT(ISBLANK(C19)), ROUND(C19/60,0), "") -> 383 | E19: 24413 | F19: =IF(NOT(ISBLANK(E19)), ROUND(E19/60,0), "") -> 407 | G19: 21874 | H19: =IF(NOT(ISBLANK(G19)), ROUND(G19/60,0), "") -> 365 | K19: 28905 | L19: =IF(NOT(ISBLANK(K19)), ROUND(K19/60,0), "") -> 482 | M19: 26944 | N19: =IF(NOT(ISBLANK(M19)), ROUND(M19/60,0), "") -> 449 | O19: 27203 | P19: =IF(NOT(ISBLANK(O19)), ROUND(O19/60,0), "") -> 453 | Q19: 27086 | R19: =IF(NOT(ISBLANK(Q19)), ROUND(Q19/60,0), "") -> 451 | S19: 24340 | T19: =IF(NOT(ISBLANK(S19)), ROUND(S19/60,0), "") -> 406 | U19: 26886 | V19: =IF(NOT(ISBLANK(U19)), ROUND(U19/60,0), "") -> 448 | W19: 23185 | X19: =IF(NOT(ISBLANK(W19)), ROUND(W19/60,0), "") -> 386 | Z19: 22641 | AA19: =IF(NOT(ISBLANK(Z19)), ROUND(Z19/60,0), "") -> 377 | AC19: 41084 (10x)
A20: 41084 (10x) | B20: 64 | C20: 20521 | D20: =IF(NOT(ISBLANK(C20)), ROUND(C20/60,0), "") -> 342 | E20: 22474 | F20: =IF(NOT(ISBLANK(E20)), ROUND(E20/60,0), "") -> 375 | G20: 19412 | H20: =IF(NOT(ISBLANK(G20)), ROUND(G20/60,0), "") -> 324 | K20: 19356 | L20: =IF(NOT(ISBLANK(K20)), ROUND(K20/60,0), "") -> 323 | M20: 20546 | N20: =IF(NOT(ISBLANK(M20)), ROUND(M20/60,0), "") -> 342 | O20: 22728 | P20: =IF(NOT(ISBLANK(O20)), ROUND(O20/60,0), "") -> 379 | Q20: 19356 | R20: =IF(NOT(ISBLANK(Q20)), ROUND(Q20/60,0), "") -> 323 | S20: 27491 | T20: =IF(NOT(ISBLANK(S20)), ROUND(S20/60,0), "") -> 458 | U20: 18981 | V20: =IF(NOT(ISBLANK(U20)), ROUND(U20/60,0), "") -> 316 | W20: 19393 | X20: =IF(NOT(ISBLANK(W20)), ROUND(W20/60,0), "") -> 323 | Z20: 19535 | AA20: =IF(NOT(ISBLANK(Z20)), ROUND(Z20/60,0), "") -> 326 | AC20: 41084 (10x)
A21: 41084 (10x) | B21: 82 | C21: 19557 | D21: =IF(NOT(ISBLANK(C21)), ROUND(C21/60,0), "") -> 326 | E21: 16924 | F21: =IF(NOT(ISBLANK(E21)), ROUND(E21/60,0), "") -> 282 | G21: 16715 | H21: =IF(NOT(ISBLANK(G21)), ROUND(G21/60,0), "") -> 279 | K21: 17864 | L21: =IF(NOT(ISBLANK(K21)), ROUND(K21/60,0), "") -> 298 | M21: 17172 | N21: =IF(NOT(ISBLANK(M21)), ROUND(M21/60,0), "") -> 286 | O21: 18452 | P21: =IF(NOT(ISBLANK(O21)), ROUND(O21/60,0), "") -> 308 | Q21: 16939 | R21: =IF(NOT(ISBLANK(Q21)), ROUND(Q21/60,0), "") -> 282 | S21: 21575 | T21: =IF(NOT(ISBLANK(S21)), ROUND(S21/60,0), "") -> 360 | U21: 20393 | V21: =IF(NOT(ISBLANK(U21)), ROUND(U21/60,0), "") -> 340 | W21: 15734 | X21: =IF(NOT(ISBLANK(W21)), ROUND(W21/60,0), "") -> 262 | Z21: 18154 | AA21: =IF(NOT(ISBLANK(Z21)), ROUND(Z21/60,0), "") -> 303 | AC21: 41084 (10x)
A22: 41084 (10x) | B22: 100 | C22: 14139 | D22: =IF(NOT(ISBLANK(C22)), ROUND(C22/60,0), "") -> 236 | E22: 15958 | F22: =IF(NOT(ISBLANK(E22)), ROUND(E22/60,0), "") -> 266 | G22: 14823 | H22: =IF(NOT(ISBLANK(G22)), ROUND(G22/60,0), "") -> 247 | K22: 16020 | L22: =IF(NOT(ISBLANK(K22)), ROUND(K22/60,0), "") -> 267 | M22: 18729 | N22: =IF(NOT(ISBLANK(M22)), ROUND(M22/60,0), "") -> 312 | O22: 18106 | P22: =IF(NOT(ISBLANK(O22)), ROUND(O22/60,0), "") -> 302 | Q22: 17175 | R22: =IF(NOT(ISBLANK(Q22)), ROUND(Q22/60,0), "") -> 286 | S22: 17745 | T22: =IF(NOT(ISBLANK(S22)), ROUND(S22/60,0), "") -> 296 | U22: 15269 | V22: =IF(NOT(ISBLANK(U22)), ROUND(U22/60,0), "") -> 254 | X22: =IF(NOT(ISBLANK(W22)), ROUND(W22/60,0), "") | Z22: 13885 | AA22: =IF(NOT(ISBLANK(Z22)), ROUND(Z22/60,0), "") -> 231 | AC22: 41084 (10x)
A23: 500094 (10x) | B23: 5 | D23: =IF(NOT(ISBLANK(C23)), ROUND(C23/60,0), "") | F23: =IF(NOT(ISBLANK(E23)), ROUND(E23/60,0), "") | H23: =IF(NOT(ISBLANK(G23)), ROUND(G23/60,0), "") | L23: =IF(NOT(ISBLANK(K23)), ROUND(K23/60,0), "") | N23: =IF(NOT(ISBLANK(M23)), ROUND(M23/60,0), "") | P23: =IF(NOT(ISBLANK(O23)), ROUND(O23/60,0), "") | R23: =IF(NOT(ISBLANK(Q23)), ROUND(Q23/60,0), "") | T23: =IF(NOT(ISBLANK(S23)), ROUND(S23/60,0), "") | V23: =IF(NOT(ISBLANK(U23)), ROUND(U23/60,0), "") | X23: =IF(NOT(ISBLANK(W23)), ROUND(W23/60,0), "") | AA23: =IF(NOT(ISBLANK(Z23)), ROUND(Z23/60,0), "") | AC23: 500094 (10x)
A24: 500094 (10x) | B24: 10 | D24: =IF(NOT(ISBLANK(C24)), ROUND(C24/60,0), "") | E24: 154798 | F24: =IF(NOT(ISBLANK(E24)), ROUND(E24/60,0), "") -> 2580 | G24: 160330 | H24: =IF(NOT(ISBLANK(G24)), ROUND(G24/60,0), "") -> 2672 | L24: =IF(NOT(ISBLANK(K24)), ROUND(K24/60,0), "") | N24: =IF(NOT(ISBLANK(M24)), ROUND(M24/60,0), "") | P24: =IF(NOT(ISBLANK(O24)), ROUND(O24/60,0), "") | R24: =IF(NOT(ISBLANK(Q24)), ROUND(Q24/60,0), "") | T24: =IF(NOT(ISBLANK(S24)), ROUND(S24/60,0), "") | V24: =IF(NOT(ISBLANK(U24)), ROUND(U24/60,0), "") | W24: 130064 | X24: =IF(NOT(ISBLANK(W24)), ROUND(W24/60,0), "") -> 2168 | AA24: =IF(NOT(ISBLANK(Z24)), ROUND(Z24/60,0), "") | AC24: 500094 (10x)
A25: 500094 (10x) | B25: 15 | C25: 96129 | D25: =IF(NOT(ISBLANK(C25)), ROUND(C25/60,0), "") -> 1602 | E25: 118996 | F25: =IF(NOT(ISBLANK(E25)), ROUND(E25/60,0), "") -> 1983 | G25: 97814 | H25: =IF(NOT(ISBLANK(G25)), ROUND(G25/60,0), "") -> 1630 | K25: 113396 | L25: =IF(NOT(ISBLANK(K25)), ROUND(K25/60,0), "") -> 1890 | N25: =IF(NOT(ISBLANK(M25)), ROUND(M25/60,0), "") | O25: 100175 | P25: =IF(NOT(ISBLANK(O25)), ROUND(O25/60,0), "") -> 1670 | Q25: 113391 | R25: =IF(NOT(ISBLANK(Q25)), ROUND(Q25/60,0), "") -> 1890 | T25: =IF(NOT(ISBLANK(S25)), ROUND(S25/60,0), "") | U25: 146357 | V25: =IF(NOT(ISBLANK(U25)), ROUND(U25/60,0), "") -> 2439 | W25: 83747 | X25: =IF(NOT(ISBLANK(W25)), ROUND(W25/60,0), "") -> 1396 | AA25: =IF(NOT(ISBLANK(Z25)), ROUND(Z25/60,0), "") | AC25: 500094 (10x)
A26: 500094 (10x) | B26: 20 | C26: 78484 | D26: =IF(NOT(ISBLANK(C26)), ROUND(C26/60,0), "") -> 1308 | E26: 106089 | F26: =IF(NOT(ISBLANK(E26)), ROUND(E26/60,0), "") -> 1768 | G26: 69487 | H26: =IF(NOT(ISBLANK(G26)), ROUND(G26/60,0), "") -> 1158 | K26: 77345 | L26: =IF(NOT(ISBLANK(K26)), ROUND(K26/60,0), "") -> 1289 | M26: 90382 | N26: =IF(NOT(ISBLANK(M26)), ROUND(M26/60,0), "") -> 1506 | O26: 78169 | P26: =IF(NOT(ISBLANK(O26)), ROUND(O26/60,0), "") -> 1303 | Q26: 77344 | R26: =IF(NOT(ISBLANK(Q26)), ROUND(Q26/60,0), "") -> 1289 | S26: 128390 | T26: =IF(NOT(ISBLANK(S26)), ROUND(S26/60,0), "") -> 2140 | U26: 116326 | V26: =IF(NOT(ISBLANK(U26)), ROUND(U26/60,0), "") -> 1939 | W26: 88432 | X26: =IF(NOT(ISBLANK(W26)), ROUND(W26/60,0), "") -> 1474 | AA26: =IF(NOT(ISBLANK(Z26)), ROUND(Z26/60,0), "") | AC26: 500094 (10x)
A27: 500094 (10x) | B27: 30 | C27: 72884 | D27: =IF(NOT(ISBLANK(C27)), ROUND(C27/60,0), "") -> 1215 | E27: 64039 | F27: =IF(NOT(ISBLANK(E27)), ROUND(E27/60,0), "") -> 1067 | G27: 54286 | H27: =IF(NOT(ISBLANK(G27)), ROUND(G27/60,0), "") -> 905 | K27: 76969 | L27: =IF(NOT(ISBLANK(K27)), ROUND(K27/60,0), "") -> 1283 | M27: 60240 | N27: =IF(NOT(ISBLANK(M27)), ROUND(M27/60,0), "") -> 1004 | O27: 58471 | P27: =IF(NOT(ISBLANK(O27)), ROUND(O27/60,0), "") -> 975 | Q27: 55714 | R27: =IF(NOT(ISBLANK(Q27)), ROUND(Q27/60,0), "") -> 929 | S27: 79904 | T27: =IF(NOT(ISBLANK(S27)), ROUND(S27/60,0), "") -> 1332 | U27: 80342 | V27: =IF(NOT(ISBLANK(U27)), ROUND(U27/60,0), "") -> 1339 | W27: 49084 | X27: =IF(NOT(ISBLANK(W27)), ROUND(W27/60,0), "") -> 818 | Z27: 70627 | AA27: =IF(NOT(ISBLANK(Z27)), ROUND(Z27/60,0), "") -> 1177 | AC27: 500094 (10x)
A28: 500094 (10x) | B28: 40 | C28: 63753 | D28: =IF(NOT(ISBLANK(C28)), ROUND(C28/60,0), "") -> 1063 | E28: 50548 | F28: =IF(NOT(ISBLANK(E28)), ROUND(E28/60,0), "") -> 842 | G28: 36254 | H28: =IF(NOT(ISBLANK(G28)), ROUND(G28/60,0), "") -> 604 | K28: 49951 | L28: =IF(NOT(ISBLANK(K28)), ROUND(K28/60,0), "") -> 833 | M28: 48527 | N28: =IF(NOT(ISBLANK(M28)), ROUND(M28/60,0), "") -> 809 | P28: =IF(NOT(ISBLANK(O28)), ROUND(O28/60,0), "") | Q28: 53537 | R28: =IF(NOT(ISBLANK(Q28)), ROUND(Q28/60,0), "") -> 892 | S28: 62525 | T28: =IF(NOT(ISBLANK(S28)), ROUND(S28/60,0), "") -> 1042 | U28: 69539 | V28: =IF(NOT(ISBLANK(U28)), ROUND(U28/60,0), "") -> 1159 | W28: 40309 | X28: =IF(NOT(ISBLANK(W28)), ROUND(W28/60,0), "") -> 672 | Z28: 69805 | AA28: =IF(NOT(ISBLANK(Z28)), ROUND(Z28/60,0), "") -> 1163 | AC28: 500094 (10x)
A29: 500094 (10x) | B29: 50 | C29: 38641 | D29: =IF(NOT(ISBLANK(C29)), ROUND(C29/60,0), "") -> 644 | E29: 42072 | F29: =IF(NOT(ISBLANK(E29)), ROUND(E29/60,0), "") -> 701 | G29: 32088 | H29: =IF(NOT(ISBLANK(G29)), ROUND(G29/60,0), "") -> 535 | K29: 38261 | L29: =IF(NOT(ISBLANK(K29)), ROUND(K29/60,0), "") -> 638 | M29: 39505 | N29: =IF(NOT(ISBLANK(M29)), ROUND(M29/60,0), "") -> 658 | O29: 36194 | P29: =IF(NOT(ISBLANK(O29)), ROUND(O29/60,0), "") -> 603 | Q29: 33826 | R29: =IF(NOT(ISBLANK(Q29)), ROUND(Q29/60,0), "") -> 564 | S29: 50264 | T29: =IF(NOT(ISBLANK(S29)), ROUND(S29/60,0), "") -> 838 | U29: 49451 | V29: =IF(NOT(ISBLANK(U29)), ROUND(U29/60,0), "") -> 824 | W29: 37592 | X29: =IF(NOT(ISBLANK(W29)), ROUND(W29/60,0), "") -> 627 | Z29: 41835 | AA29: =IF(NOT(ISBLANK(Z29)), ROUND(Z29/60,0), "") -> 697 | AC29: 500094 (10x)
A30: 500094 (10x) | B30: 64 | C30: 28973 | D30: =IF(NOT(ISBLANK(C30)), ROUND(C30/60,0), "") -> 483 | E30: 33213 | F30: =IF(NOT(ISBLANK(E30)), ROUND(E30/60,0), "") -> 554 | G30: 29429 | H30: =IF(NOT(ISBLANK(G30)), ROUND(G30/60,0), "") -> 490 | K30: 31039 | L30: =IF(NOT(ISBLANK(K30)), ROUND(K30/60,0), "") -> 517 | M30: 33024 | N30: =IF(NOT(ISBLANK(M30)), ROUND(M30/60,0), "") -> 550 | O30: 31260 | P30: =IF(NOT(ISBLANK(O30)), ROUND(O30/60,0), "") -> 521 | Q30: 31353 | R30: =IF(NOT(ISBLANK(Q30)), ROUND(Q30/60,0), "") -> 523 | S30: 35305 | T30: =IF(NOT(ISBLANK(S30)), ROUND(S30/60,0), "") -> 588 | U30: 60641 | V30: =IF(NOT(ISBLANK(U30)), ROUND(U30/60,0), "") -> 1011 | W30: 31359 | X30: =IF(NOT(ISBLANK(W30)), ROUND(W30/60,0), "") -> 523 | Z30: 41884 | AA30: =IF(NOT(ISBLANK(Z30)), ROUND(Z30/60,0), "") -> 698 | AC30: 500094 (10x)
A31: 500094 (10x) | B31: 82 | C31: 28103 | D31: =IF(NOT(ISBLANK(C31)), ROUND(C31/60,0), "") -> 468 | E31: 23494 | F31: =IF(NOT(ISBLANK(E31)), ROUND(E31/60,0), "") -> 392 | G31: 22925 | H31: =IF(NOT(ISBLANK(G31)), ROUND(G31/60,0), "") -> 382 | K31: 25374 | L31: =IF(NOT(ISBLANK(K31)), ROUND(K31/60,0), "") -> 423 | M31: 24903 | N31: =IF(NOT(ISBLANK(M31)), ROUND(M31/60,0), "") -> 415 | O31: 27334 | P31: =IF(NOT(ISBLANK(O31)), ROUND(O31/60,0), "") -> 456 | Q31: 28245 | R31: =IF(NOT(ISBLANK(Q31)), ROUND(Q31/60,0), "") -> 471 | S31: 35287 | T31: =IF(NOT(ISBLANK(S31)), ROUND(S31/60,0), "") -> 588 | U31: 57777 | V31: =IF(NOT(ISBLANK(U31)), ROUND(U31/60,0), "") -> 963 | W31: 34921 | X31: =IF(NOT(ISBLANK(W31)), ROUND(W31/60,0), "") -> 582 | Z31: 35747 | AA31: =IF(NOT(ISBLANK(Z31)), ROUND(Z31/60,0), "") -> 596 | AC31: 500094 (10x)
A32: 500094 (10x) | B32: 100 | C32: 20135 | D32: =IF(NOT(ISBLANK(C32)), ROUND(C32/60,0), "") -> 336 | E32: 33007 | F32: =IF(NOT(ISBLANK(E32)), ROUND(E32/60,0), "") -> 550 | G32: 21181 | H32: =IF(NOT(ISBLANK(G32)), ROUND(G32/60,0), "") -> 353 | K32: 24874 | L32: =IF(NOT(ISBLANK(K32)), ROUND(K32/60,0), "") -> 415 | M32: 25267 | N32: =IF(NOT(ISBLANK(M32)), ROUND(M32/60,0), "") -> 421 | O32: 22917 | P32: =IF(NOT(ISBLANK(O32)), ROUND(O32/60,0), "") -> 382 | Q32: 23305 | R32: =IF(NOT(ISBLANK(Q32)), ROUND(Q32/60,0), "") -> 388 | S32: 34052 | T32: =IF(NOT(ISBLANK(S32)), ROUND(S32/60,0), "") -> 568 | U32: 31612 | V32: =IF(NOT(ISBLANK(U32)), ROUND(U32/60,0), "") -> 527 | X32: =IF(NOT(ISBLANK(W32)), ROUND(W32/60,0), "") | Z32: 26217 | AA32: =IF(NOT(ISBLANK(Z32)), ROUND(Z32/60,0), "") -> 437 | AC32: 500094 (10x)
A33: 51329 (4x) | B33: 5 | D33: =IF(NOT(ISBLANK(C33)), ROUND(C33/60,0), "") | F33: =IF(NOT(ISBLANK(E33)), ROUND(E33/60,0), "") | H33: =IF(NOT(ISBLANK(G33)), ROUND(G33/60,0), "") | L33: =IF(NOT(ISBLANK(K33)), ROUND(K33/60,0), "") | N33: =IF(NOT(ISBLANK(M33)), ROUND(M33/60,0), "") | P33: =IF(NOT(ISBLANK(O33)), ROUND(O33/60,0), "") | R33: =IF(NOT(ISBLANK(Q33)), ROUND(Q33/60,0), "") | T33: =IF(NOT(ISBLANK(S33)), ROUND(S33/60,0), "") | V33: =IF(NOT(ISBLANK(U33)), ROUND(U33/60,0), "") | W33: 57504 | X33: =IF(NOT(ISBLANK(W33)), ROUND(W33/60,0), "") -> 958 | AA33: =IF(NOT(ISBLANK(Z33)), ROUND(Z33/60,0), "") | AC33: 51329 (4x)
A34: 51329 (4x) | B34: 10 | C34: 69029 | D34: =IF(NOT(ISBLANK(C34)), ROUND(C34/60,0), "") -> 1150 | E34: 60207 | F34: =IF(NOT(ISBLANK(E34)), ROUND(E34/60,0), "") -> 1003 | H34: =IF(NOT(ISBLANK(G34)), ROUND(G34/60,0), "") | L34: =IF(NOT(ISBLANK(K34)), ROUND(K34/60,0), "") | N34: =IF(NOT(ISBLANK(M34)), ROUND(M34/60,0), "") | O34: 73070 | P34: =IF(NOT(ISBLANK(O34)), ROUND(O34/60,0), "") -> 1218 | Q34: 63332 | R34: =IF(NOT(ISBLANK(Q34)), ROUND(Q34/60,0), "") -> 1056 | S34: 69805 | T34: =IF(NOT(ISBLANK(S34)), ROUND(S34/60,0), "") -> 1163 | U34: 83196 | V34: =IF(NOT(ISBLANK(U34)), ROUND(U34/60,0), "") -> 1387 | W34: 45677 | X34: =IF(NOT(ISBLANK(W34)), ROUND(W34/60,0), "") -> 761 | Z34: 62880 | AA34: =IF(NOT(ISBLANK(Z34)), ROUND(Z34/60,0), "") -> 1048 | AC34: 51329 (4x)
A35: 51329 (4x) | B35: 15 | D35: =IF(NOT(ISBLANK(C35)), ROUND(C35/60,0), "") | E35: 55803 | F35: =IF(NOT(ISBLANK(E35)), ROUND(E35/60,0), "") -> 930 | G35: 46704 | H35: =IF(NOT(ISBLANK(G35)), ROUND(G35/60,0), "") -> 778 | K35: 50516 | L35: =IF(NOT(ISBLANK(K35)), ROUND(K35/60,0), "") -> 842 | M35: 50690 | N35: =IF(NOT(ISBLANK(M35)), ROUND(M35/60,0), "") -> 845 | O35: 58908 | P35: =IF(NOT(ISBLANK(O35)), ROUND(O35/60,0), "") -> 982 | Q35: 53349 | R35: =IF(NOT(ISBLANK(Q35)), ROUND(Q35/60,0), "") -> 889 | S35: 49390 | T35: =IF(NOT(ISBLANK(S35)), ROUND(S35/60,0), "") -> 823 | U35: 60429 | V35: =IF(NOT(ISBLANK(U35)), ROUND(U35/60,0), "") -> 1007 | W35: 36901 | X35: =IF(NOT(ISBLANK(W35)), ROUND(W35/60,0), "") -> 615 | Z35: 48352 | AA35: =IF(NOT(ISBLANK(Z35)), ROUND(Z35/60,0), "") -> 806 | AC35: 51329 (4x)
A36: 51329 (4x) | B36: 20 | C36: 41130 | D36: =IF(NOT(ISBLANK(C36)), ROUND(C36/60,0), "") -> 686 | E36: 40808 | F36: =IF(NOT(ISBLANK(E36)), ROUND(E36/60,0), "") -> 680 | G36: 41658 | H36: =IF(NOT(ISBLANK(G36)), ROUND(G36/60,0), "") -> 694 | K36: 40868 | L36: =IF(NOT(ISBLANK(K36)), ROUND(K36/60,0), "") -> 681 | M36: 44528 | N36: =IF(NOT(ISBLANK(M36)), ROUND(M36/60,0), "") -> 742 | O36: 35323 | P36: =IF(NOT(ISBLANK(O36)), ROUND(O36/60,0), "") -> 589 | Q36: 39933 | R36: =IF(NOT(ISBLANK(Q36)), ROUND(Q36/60,0), "") -> 666 | S36: 38605 | T36: =IF(NOT(ISBLANK(S36)), ROUND(S36/60,0), "") -> 643 | U36: 45401 | V36: =IF(NOT(ISBLANK(U36)), ROUND(U36/60,0), "") -> 757 | W36: 26447 | X36: =IF(NOT(ISBLANK(W36)), ROUND(W36/60,0), "") -> 441 | Z36: 37233 | AA36: =IF(NOT(ISBLANK(Z36)), ROUND(Z36/60,0), "") -> 621 | AC36: 51329 (4x)
A37: 51329 (4x) | B37: 30 | C37: 33168 | D37: =IF(NOT(ISBLANK(C37)), ROUND(C37/60,0), "") -> 553 | E37: 30769 | F37: =IF(NOT(ISBLANK(E37)), ROUND(E37/60,0), "") -> 513 | G37: 34193 | H37: =IF(NOT(ISBLANK(G37)), ROUND(G37/60,0), "") -> 570 | K37: 31088 | L37: =IF(NOT(ISBLANK(K37)), ROUND(K37/60,0), "") -> 518 | M37: 27074 | N37: =IF(NOT(ISBLANK(M37)), ROUND(M37/60,0), "") -> 451 | O37: 26096 | P37: =IF(NOT(ISBLANK(O37)), ROUND(O37/60,0), "") -> 435 | Q37: 31449 | R37: =IF(NOT(ISBLANK(Q37)), ROUND(Q37/60,0), "") -> 524 | S37: 26802 | T37: =IF(NOT(ISBLANK(S37)), ROUND(S37/60,0), "") -> 447 | U37: 44043 | V37: =IF(NOT(ISBLANK(U37)), ROUND(U37/60,0), "") -> 734 | W37: 21092 | X37: =IF(NOT(ISBLANK(W37)), ROUND(W37/60,0), "") -> 352 | Z37: 27985 | AA37: =IF(NOT(ISBLANK(Z37)), ROUND(Z37/60,0), "") -> 466 | AC37: 51329 (4x)
A38: 51329 (4x) | B38: 40 | C38: 26222 | D38: =IF(NOT(ISBLANK(C38)), ROUND(C38/60,0), "") -> 437 | E38: 23741 | F38: =IF(NOT(ISBLANK(E38)), ROUND(E38/60,0), "") -> 396 | G38: 22696 | H38: =IF(NOT(ISBLANK(G38)), ROUND(G38/60,0), "") -> 378 | K38: 21955 | L38: =IF(NOT(ISBLANK(K38)), ROUND(K38/60,0), "") -> 366 | M38: 24077 | N38: =IF(NOT(ISBLANK(M38)), ROUND(M38/60,0), "") -> 401 | O38: 20839 | P38: =IF(NOT(ISBLANK(O38)), ROUND(O38/60,0), "") -> 347 | Q38: 22638 | R38: =IF(NOT(ISBLANK(Q38)), ROUND(Q38/60,0), "") -> 377 | S38: 24719 | T38: =IF(NOT(ISBLANK(S38)), ROUND(S38/60,0), "") -> 412 | U38: 25393 | V38: =IF(NOT(ISBLANK(U38)), ROUND(U38/60,0), "") -> 423 | W38: 18786 | X38: =IF(NOT(ISBLANK(W38)), ROUND(W38/60,0), "") -> 313 | Z38: 21382 | AA38: =IF(NOT(ISBLANK(Z38)), ROUND(Z38/60,0), "") -> 356 | AC38: 51329 (4x)
A39: 51329 (4x) | B39: 50 | C39: 19630 | D39: =IF(NOT(ISBLANK(C39)), ROUND(C39/60,0), "") -> 327 | E39: 19530 | F39: =IF(NOT(ISBLANK(E39)), ROUND(E39/60,0), "") -> 326 | G39: 19532 | H39: =IF(NOT(ISBLANK(G39)), ROUND(G39/60,0), "") -> 326 | K39: 21176 | L39: =IF(NOT(ISBLANK(K39)), ROUND(K39/60,0), "") -> 353 | M39: 22052 | N39: =IF(NOT(ISBLANK(M39)), ROUND(M39/60,0), "") -> 368 | O39: 24509 | P39: =IF(NOT(ISBLANK(O39)), ROUND(O39/60,0), "") -> 408 | Q39: 20615 | R39: =IF(NOT(ISBLANK(Q39)), ROUND(Q39/60,0), "") -> 344 | S39: 19708 | T39: =IF(NOT(ISBLANK(S39)), ROUND(S39/60,0), "") -> 328 | U39: 18616 | V39: =IF(NOT(ISBLANK(U39)), ROUND(U39/60,0), "") -> 310 | W39: 14880 | X39: =IF(NOT(ISBLANK(W39)), ROUND(W39/60,0), "") -> 248 | Z39: 19082 | AA39: =IF(NOT(ISBLANK(Z39)), ROUND(Z39/60,0), "") -> 318 | AC39: 51329 (4x)
A40: 51329 (4x) | B40: 64 | C40: 16549 | D40: =IF(NOT(ISBLANK(C40)), ROUND(C40/60,0), "") -> 276 | E40: 17146 | F40: =IF(NOT(ISBLANK(E40)), ROUND(E40/60,0), "") -> 286 | G40: 17315 | H40: =IF(NOT(ISBLANK(G40)), ROUND(G40/60,0), "") -> 289 | K40: 16191 | L40: =IF(NOT(ISBLANK(K40)), ROUND(K40/60,0), "") -> 270 | M40: 17622 | N40: =IF(NOT(ISBLANK(M40)), ROUND(M40/60,0), "") -> 294 | O40: 15985 | P40: =IF(NOT(ISBLANK(O40)), ROUND(O40/60,0), "") -> 266 | Q40: 16310 | R40: =IF(NOT(ISBLANK(Q40)), ROUND(Q40/60,0), "") -> 272 | S40: 16007 | T40: =IF(NOT(ISBLANK(S40)), ROUND(S40/60,0), "") -> 267 | U40: 15958 | V40: =IF(NOT(ISBLANK(U40)), ROUND(U40/60,0), "") -> 266 | W40: 15213 | X40: =IF(NOT(ISBLANK(W40)), ROUND(W40/60,0), "") -> 254 | Z40: 16248 | AA40: =IF(NOT(ISBLANK(Z40)), ROUND(Z40/60,0), "") -> 271 | AC40: 51329 (4x)
...

Sheet Representative
B1: Model | C1: 5 | D1: 10 | E1: 15 | F1: 20 | G1: 30 | H1: 40 | I1: 50 | J1: 64 | K1: 82 | L1: 100 | M1: CV %
B2: 1053374 (25x) | D2: 2056 | E2: 1016 | F2: 755 | G2: 645 | H2: 500 | I2: 405 | J2: 389 | K2: 363 | L2: 278 | M2: =MEDIAN('Statistical Analysis'!AB5:AB13) -> 0.096335743
